2024-08-11T08:14:39.054Z - Error generating graph for Knee OA Fatigue for Mr_no: 55 - Error: Command failed: python3 python_scripts/script-d3.py 55 "Knee OA Fatigue"
Traceback (most recent call last):
  File "/Users/vijaychagantipati/Documents/Developer/node projects/proms/Doctor_Login_Page/python_scripts/script-d3.py", line 2301, in <module>
    combine_all_csvs(mr_no)
  File "/Users/vijaychagantipati/Documents/Developer/node projects/proms/Doctor_Login_Page/python_scripts/script-d3.py", line 1545, in combine_all_csvs
    df = pd.read_csv(csv_file)
         ^^^^^^^^^^^^^^^^^^^^^
  File "/opt/anaconda3/lib/python3.11/site-packages/pandas/io/parsers/readers.py", line 948, in read_csv
    return _read(filepath_or_buffer, kwds)
           ^^^^^^^^^^^^^^^^^^^^^^^^^^^^^^^
  File "/opt/anaconda3/lib/python3.11/site-packages/pandas/io/parsers/readers.py", line 611, in _read
    parser = TextFileReader(filepath_or_buffer, **kwds)
             ^^^^^^^^^^^^^^^^^^^^^^^^^^^^^^^^^^^^^^^^^^
  File "/opt/anaconda3/lib/python3.11/site-packages/pandas/io/parsers/readers.py", line 1448, in __init__
    self._engine = self._make_engine(f, self.engine)
                   ^^^^^^^^^^^^^^^^^^^^^^^^^^^^^^^^^
  File "/opt/anaconda3/lib/python3.11/site-packages/pandas/io/parsers/readers.py", line 1723, in _make_engine
    return mapping[engine](f, **self.options)
           ^^^^^^^^^^^^^^^^^^^^^^^^^^^^^^^^^^
  File "/opt/anaconda3/lib/python3.11/site-packages/pandas/io/parsers/c_parser_wrapper.py", line 93, in __init__
    self._reader = parsers.TextReader(src, **kwds)
                   ^^^^^^^^^^^^^^^^^^^^^^^^^^^^^^^
  File "parsers.pyx", line 586, in pandas._libs.parsers.TextReader.__cinit__
pandas.errors.EmptyDataError: No columns to parse from file

2024-08-11T08:23:51.110Z - Error generating graph for Wexner for Mr_no: 66 - Error: Command failed: python3 python_scripts/script-d3.py 66 "Wexner"
Traceback (most recent call last):
  File "/opt/anaconda3/lib/python3.11/site-packages/pandas/core/indexes/base.py", line 3791, in get_loc
    return self._engine.get_loc(casted_key)
           ^^^^^^^^^^^^^^^^^^^^^^^^^^^^^^^^
  File "index.pyx", line 152, in pandas._libs.index.IndexEngine.get_loc
  File "index.pyx", line 181, in pandas._libs.index.IndexEngine.get_loc
  File "pandas/_libs/hashtable_class_helper.pxi", line 7080, in pandas._libs.hashtable.PyObjectHashTable.get_item
  File "pandas/_libs/hashtable_class_helper.pxi", line 7088, in pandas._libs.hashtable.PyObjectHashTable.get_item
KeyError: 'trace_name'

The above exception was the direct cause of the following exception:

Traceback (most recent call last):
  File "/Users/vijaychagantipati/Documents/Developer/node projects/proms/Doctor_Login_Page/python_scripts/script-d3.py", line 2301, in <module>
    combine_all_csvs(mr_no)
  File "/Users/vijaychagantipati/Documents/Developer/node projects/proms/Doctor_Login_Page/python_scripts/script-d3.py", line 1561, in combine_all_csvs
    combined_df['trace_name'] = combined_df['trace_name'].replace({
                                ~~~~~~~~~~~^^^^^^^^^^^^^^
  File "/opt/anaconda3/lib/python3.11/site-packages/pandas/core/frame.py", line 3893, in __getitem__
    indexer = self.columns.get_loc(key)
              ^^^^^^^^^^^^^^^^^^^^^^^^^
  File "/opt/anaconda3/lib/python3.11/site-packages/pandas/core/indexes/base.py", line 3798, in get_loc
    raise KeyError(key) from err
KeyError: 'trace_name'

2024-08-11T08:23:51.120Z - Error generating graph for PROMIS-10 for Mr_no: 66 - Error: Command failed: python3 python_scripts/script-d3.py 66 "PROMIS-10"
Traceback (most recent call last):
  File "/opt/anaconda3/lib/python3.11/site-packages/pandas/core/indexes/base.py", line 3791, in get_loc
    return self._engine.get_loc(casted_key)
           ^^^^^^^^^^^^^^^^^^^^^^^^^^^^^^^^
  File "index.pyx", line 152, in pandas._libs.index.IndexEngine.get_loc
  File "index.pyx", line 181, in pandas._libs.index.IndexEngine.get_loc
  File "pandas/_libs/hashtable_class_helper.pxi", line 7080, in pandas._libs.hashtable.PyObjectHashTable.get_item
  File "pandas/_libs/hashtable_class_helper.pxi", line 7088, in pandas._libs.hashtable.PyObjectHashTable.get_item
KeyError: 'trace_name'

The above exception was the direct cause of the following exception:

Traceback (most recent call last):
  File "/Users/vijaychagantipati/Documents/Developer/node projects/proms/Doctor_Login_Page/python_scripts/script-d3.py", line 2301, in <module>
    combine_all_csvs(mr_no)
  File "/Users/vijaychagantipati/Documents/Developer/node projects/proms/Doctor_Login_Page/python_scripts/script-d3.py", line 1561, in combine_all_csvs
    combined_df['trace_name'] = combined_df['trace_name'].replace({
                                ~~~~~~~~~~~^^^^^^^^^^^^^^
  File "/opt/anaconda3/lib/python3.11/site-packages/pandas/core/frame.py", line 3893, in __getitem__
    indexer = self.columns.get_loc(key)
              ^^^^^^^^^^^^^^^^^^^^^^^^^
  File "/opt/anaconda3/lib/python3.11/site-packages/pandas/core/indexes/base.py", line 3798, in get_loc
    raise KeyError(key) from err
KeyError: 'trace_name'

2024-08-11T08:23:51.122Z - Error generating graph for EPDS for Mr_no: 66 - Error: Command failed: python3 python_scripts/script-d3.py 66 "EPDS"
Traceback (most recent call last):
  File "/opt/anaconda3/lib/python3.11/site-packages/pandas/core/indexes/base.py", line 3791, in get_loc
    return self._engine.get_loc(casted_key)
           ^^^^^^^^^^^^^^^^^^^^^^^^^^^^^^^^
  File "index.pyx", line 152, in pandas._libs.index.IndexEngine.get_loc
  File "index.pyx", line 181, in pandas._libs.index.IndexEngine.get_loc
  File "pandas/_libs/hashtable_class_helper.pxi", line 7080, in pandas._libs.hashtable.PyObjectHashTable.get_item
  File "pandas/_libs/hashtable_class_helper.pxi", line 7088, in pandas._libs.hashtable.PyObjectHashTable.get_item
KeyError: 'trace_name'

The above exception was the direct cause of the following exception:

Traceback (most recent call last):
  File "/Users/vijaychagantipati/Documents/Developer/node projects/proms/Doctor_Login_Page/python_scripts/script-d3.py", line 2301, in <module>
    combine_all_csvs(mr_no)
  File "/Users/vijaychagantipati/Documents/Developer/node projects/proms/Doctor_Login_Page/python_scripts/script-d3.py", line 1561, in combine_all_csvs
    combined_df['trace_name'] = combined_df['trace_name'].replace({
                                ~~~~~~~~~~~^^^^^^^^^^^^^^
  File "/opt/anaconda3/lib/python3.11/site-packages/pandas/core/frame.py", line 3893, in __getitem__
    indexer = self.columns.get_loc(key)
              ^^^^^^^^^^^^^^^^^^^^^^^^^
  File "/opt/anaconda3/lib/python3.11/site-packages/pandas/core/indexes/base.py", line 3798, in get_loc
    raise KeyError(key) from err
KeyError: 'trace_name'

2024-08-11T08:23:51.130Z - Error generating graph for ICIQ-UI_SF for Mr_no: 66 - Error: Command failed: python3 python_scripts/script-d3.py 66 "ICIQ-UI_SF"
Traceback (most recent call last):
  File "/opt/anaconda3/lib/python3.11/site-packages/pandas/core/indexes/base.py", line 3791, in get_loc
    return self._engine.get_loc(casted_key)
           ^^^^^^^^^^^^^^^^^^^^^^^^^^^^^^^^
  File "index.pyx", line 152, in pandas._libs.index.IndexEngine.get_loc
  File "index.pyx", line 181, in pandas._libs.index.IndexEngine.get_loc
  File "pandas/_libs/hashtable_class_helper.pxi", line 7080, in pandas._libs.hashtable.PyObjectHashTable.get_item
  File "pandas/_libs/hashtable_class_helper.pxi", line 7088, in pandas._libs.hashtable.PyObjectHashTable.get_item
KeyError: 'trace_name'

The above exception was the direct cause of the following exception:

Traceback (most recent call last):
  File "/Users/vijaychagantipati/Documents/Developer/node projects/proms/Doctor_Login_Page/python_scripts/script-d3.py", line 2301, in <module>
    combine_all_csvs(mr_no)
  File "/Users/vijaychagantipati/Documents/Developer/node projects/proms/Doctor_Login_Page/python_scripts/script-d3.py", line 1561, in combine_all_csvs
    combined_df['trace_name'] = combined_df['trace_name'].replace({
                                ~~~~~~~~~~~^^^^^^^^^^^^^^
  File "/opt/anaconda3/lib/python3.11/site-packages/pandas/core/frame.py", line 3893, in __getitem__
    indexer = self.columns.get_loc(key)
              ^^^^^^^^^^^^^^^^^^^^^^^^^
  File "/opt/anaconda3/lib/python3.11/site-packages/pandas/core/indexes/base.py", line 3798, in get_loc
    raise KeyError(key) from err
KeyError: 'trace_name'

2024-08-11T08:23:53.274Z - Error generating graph for ICIQ-UI_SF for Mr_no: 66 - Error: Command failed: python3 python_scripts/script-d3.py 66 "ICIQ-UI_SF"
Traceback (most recent call last):
  File "/opt/anaconda3/lib/python3.11/site-packages/pandas/core/indexes/base.py", line 3791, in get_loc
    return self._engine.get_loc(casted_key)
           ^^^^^^^^^^^^^^^^^^^^^^^^^^^^^^^^
  File "index.pyx", line 152, in pandas._libs.index.IndexEngine.get_loc
  File "index.pyx", line 181, in pandas._libs.index.IndexEngine.get_loc
  File "pandas/_libs/hashtable_class_helper.pxi", line 7080, in pandas._libs.hashtable.PyObjectHashTable.get_item
  File "pandas/_libs/hashtable_class_helper.pxi", line 7088, in pandas._libs.hashtable.PyObjectHashTable.get_item
KeyError: 'trace_name'

The above exception was the direct cause of the following exception:

Traceback (most recent call last):
  File "/Users/vijaychagantipati/Documents/Developer/node projects/proms/Doctor_Login_Page/python_scripts/script-d3.py", line 2301, in <module>
    combine_all_csvs(mr_no)
  File "/Users/vijaychagantipati/Documents/Developer/node projects/proms/Doctor_Login_Page/python_scripts/script-d3.py", line 1561, in combine_all_csvs
    combined_df['trace_name'] = combined_df['trace_name'].replace({
                                ~~~~~~~~~~~^^^^^^^^^^^^^^
  File "/opt/anaconda3/lib/python3.11/site-packages/pandas/core/frame.py", line 3893, in __getitem__
    indexer = self.columns.get_loc(key)
              ^^^^^^^^^^^^^^^^^^^^^^^^^
  File "/opt/anaconda3/lib/python3.11/site-packages/pandas/core/indexes/base.py", line 3798, in get_loc
    raise KeyError(key) from err
KeyError: 'trace_name'

2024-08-11T08:23:53.275Z - Error generating graph for Wexner for Mr_no: 66 - Error: Command failed: python3 python_scripts/script-d3.py 66 "Wexner"
Traceback (most recent call last):
  File "/opt/anaconda3/lib/python3.11/site-packages/pandas/core/indexes/base.py", line 3791, in get_loc
    return self._engine.get_loc(casted_key)
           ^^^^^^^^^^^^^^^^^^^^^^^^^^^^^^^^
  File "index.pyx", line 152, in pandas._libs.index.IndexEngine.get_loc
  File "index.pyx", line 181, in pandas._libs.index.IndexEngine.get_loc
  File "pandas/_libs/hashtable_class_helper.pxi", line 7080, in pandas._libs.hashtable.PyObjectHashTable.get_item
  File "pandas/_libs/hashtable_class_helper.pxi", line 7088, in pandas._libs.hashtable.PyObjectHashTable.get_item
KeyError: 'trace_name'

The above exception was the direct cause of the following exception:

Traceback (most recent call last):
  File "/Users/vijaychagantipati/Documents/Developer/node projects/proms/Doctor_Login_Page/python_scripts/script-d3.py", line 2301, in <module>
    combine_all_csvs(mr_no)
  File "/Users/vijaychagantipati/Documents/Developer/node projects/proms/Doctor_Login_Page/python_scripts/script-d3.py", line 1561, in combine_all_csvs
    combined_df['trace_name'] = combined_df['trace_name'].replace({
                                ~~~~~~~~~~~^^^^^^^^^^^^^^
  File "/opt/anaconda3/lib/python3.11/site-packages/pandas/core/frame.py", line 3893, in __getitem__
    indexer = self.columns.get_loc(key)
              ^^^^^^^^^^^^^^^^^^^^^^^^^
  File "/opt/anaconda3/lib/python3.11/site-packages/pandas/core/indexes/base.py", line 3798, in get_loc
    raise KeyError(key) from err
KeyError: 'trace_name'

2024-08-11T08:23:53.278Z - Error generating graph for EPDS for Mr_no: 66 - Error: Command failed: python3 python_scripts/script-d3.py 66 "EPDS"
Traceback (most recent call last):
  File "/opt/anaconda3/lib/python3.11/site-packages/pandas/core/indexes/base.py", line 3791, in get_loc
    return self._engine.get_loc(casted_key)
           ^^^^^^^^^^^^^^^^^^^^^^^^^^^^^^^^
  File "index.pyx", line 152, in pandas._libs.index.IndexEngine.get_loc
  File "index.pyx", line 181, in pandas._libs.index.IndexEngine.get_loc
  File "pandas/_libs/hashtable_class_helper.pxi", line 7080, in pandas._libs.hashtable.PyObjectHashTable.get_item
  File "pandas/_libs/hashtable_class_helper.pxi", line 7088, in pandas._libs.hashtable.PyObjectHashTable.get_item
KeyError: 'trace_name'

The above exception was the direct cause of the following exception:

Traceback (most recent call last):
  File "/Users/vijaychagantipati/Documents/Developer/node projects/proms/Doctor_Login_Page/python_scripts/script-d3.py", line 2301, in <module>
    combine_all_csvs(mr_no)
  File "/Users/vijaychagantipati/Documents/Developer/node projects/proms/Doctor_Login_Page/python_scripts/script-d3.py", line 1561, in combine_all_csvs
    combined_df['trace_name'] = combined_df['trace_name'].replace({
                                ~~~~~~~~~~~^^^^^^^^^^^^^^
  File "/opt/anaconda3/lib/python3.11/site-packages/pandas/core/frame.py", line 3893, in __getitem__
    indexer = self.columns.get_loc(key)
              ^^^^^^^^^^^^^^^^^^^^^^^^^
  File "/opt/anaconda3/lib/python3.11/site-packages/pandas/core/indexes/base.py", line 3798, in get_loc
    raise KeyError(key) from err
KeyError: 'trace_name'

2024-08-11T08:23:53.278Z - Error generating graph for PROMIS-10 for Mr_no: 66 - Error: Command failed: python3 python_scripts/script-d3.py 66 "PROMIS-10"
Traceback (most recent call last):
  File "/opt/anaconda3/lib/python3.11/site-packages/pandas/core/indexes/base.py", line 3791, in get_loc
    return self._engine.get_loc(casted_key)
           ^^^^^^^^^^^^^^^^^^^^^^^^^^^^^^^^
  File "index.pyx", line 152, in pandas._libs.index.IndexEngine.get_loc
  File "index.pyx", line 181, in pandas._libs.index.IndexEngine.get_loc
  File "pandas/_libs/hashtable_class_helper.pxi", line 7080, in pandas._libs.hashtable.PyObjectHashTable.get_item
  File "pandas/_libs/hashtable_class_helper.pxi", line 7088, in pandas._libs.hashtable.PyObjectHashTable.get_item
KeyError: 'trace_name'

The above exception was the direct cause of the following exception:

Traceback (most recent call last):
  File "/Users/vijaychagantipati/Documents/Developer/node projects/proms/Doctor_Login_Page/python_scripts/script-d3.py", line 2301, in <module>
    combine_all_csvs(mr_no)
  File "/Users/vijaychagantipati/Documents/Developer/node projects/proms/Doctor_Login_Page/python_scripts/script-d3.py", line 1561, in combine_all_csvs
    combined_df['trace_name'] = combined_df['trace_name'].replace({
                                ~~~~~~~~~~~^^^^^^^^^^^^^^
  File "/opt/anaconda3/lib/python3.11/site-packages/pandas/core/frame.py", line 3893, in __getitem__
    indexer = self.columns.get_loc(key)
              ^^^^^^^^^^^^^^^^^^^^^^^^^
  File "/opt/anaconda3/lib/python3.11/site-packages/pandas/core/indexes/base.py", line 3798, in get_loc
    raise KeyError(key) from err
KeyError: 'trace_name'

2024-08-11T09:43:21.654Z - Error generating graph for Pain Interference for Mr_no: 66 - Error: Command failed: python3 python_scripts/script-d3.py 66 "Pain Interference"
Traceback (most recent call last):
  File "/Users/vijaychagantipati/Documents/Developer/node projects/proms/Doctor_Login_Page/python_scripts/script-d3.py", line 2301, in <module>
    combine_all_csvs(mr_no)
  File "/Users/vijaychagantipati/Documents/Developer/node projects/proms/Doctor_Login_Page/python_scripts/script-d3.py", line 1545, in combine_all_csvs
    df = pd.read_csv(csv_file)
         ^^^^^^^^^^^^^^^^^^^^^
  File "/opt/anaconda3/lib/python3.11/site-packages/pandas/io/parsers/readers.py", line 948, in read_csv
    return _read(filepath_or_buffer, kwds)
           ^^^^^^^^^^^^^^^^^^^^^^^^^^^^^^^
  File "/opt/anaconda3/lib/python3.11/site-packages/pandas/io/parsers/readers.py", line 611, in _read
    parser = TextFileReader(filepath_or_buffer, **kwds)
             ^^^^^^^^^^^^^^^^^^^^^^^^^^^^^^^^^^^^^^^^^^
  File "/opt/anaconda3/lib/python3.11/site-packages/pandas/io/parsers/readers.py", line 1448, in __init__
    self._engine = self._make_engine(f, self.engine)
                   ^^^^^^^^^^^^^^^^^^^^^^^^^^^^^^^^^
  File "/opt/anaconda3/lib/python3.11/site-packages/pandas/io/parsers/readers.py", line 1723, in _make_engine
    return mapping[engine](f, **self.options)
           ^^^^^^^^^^^^^^^^^^^^^^^^^^^^^^^^^^
  File "/opt/anaconda3/lib/python3.11/site-packages/pandas/io/parsers/c_parser_wrapper.py", line 93, in __init__
    self._reader = parsers.TextReader(src, **kwds)
                   ^^^^^^^^^^^^^^^^^^^^^^^^^^^^^^^
  File "parsers.pyx", line 586, in pandas._libs.parsers.TextReader.__cinit__
pandas.errors.EmptyDataError: No columns to parse from file

2024-08-11T10:09:52.436Z - Error generating graph for Knee OA Fatigue for Mr_no: 66 - Error: Command failed: python3 python_scripts/script-d3.py 66 "Knee OA Fatigue"
Traceback (most recent call last):
  File "/Users/vijaychagantipati/Documents/Developer/node projects/proms/Doctor_Login_Page/python_scripts/script-d3.py", line 2301, in <module>
    combine_all_csvs(mr_no)
  File "/Users/vijaychagantipati/Documents/Developer/node projects/proms/Doctor_Login_Page/python_scripts/script-d3.py", line 1545, in combine_all_csvs
    df = pd.read_csv(csv_file)
         ^^^^^^^^^^^^^^^^^^^^^
  File "/opt/anaconda3/lib/python3.11/site-packages/pandas/io/parsers/readers.py", line 948, in read_csv
    return _read(filepath_or_buffer, kwds)
           ^^^^^^^^^^^^^^^^^^^^^^^^^^^^^^^
  File "/opt/anaconda3/lib/python3.11/site-packages/pandas/io/parsers/readers.py", line 611, in _read
    parser = TextFileReader(filepath_or_buffer, **kwds)
             ^^^^^^^^^^^^^^^^^^^^^^^^^^^^^^^^^^^^^^^^^^
  File "/opt/anaconda3/lib/python3.11/site-packages/pandas/io/parsers/readers.py", line 1448, in __init__
    self._engine = self._make_engine(f, self.engine)
                   ^^^^^^^^^^^^^^^^^^^^^^^^^^^^^^^^^
  File "/opt/anaconda3/lib/python3.11/site-packages/pandas/io/parsers/readers.py", line 1723, in _make_engine
    return mapping[engine](f, **self.options)
           ^^^^^^^^^^^^^^^^^^^^^^^^^^^^^^^^^^
  File "/opt/anaconda3/lib/python3.11/site-packages/pandas/io/parsers/c_parser_wrapper.py", line 93, in __init__
    self._reader = parsers.TextReader(src, **kwds)
                   ^^^^^^^^^^^^^^^^^^^^^^^^^^^^^^^
  File "parsers.pyx", line 586, in pandas._libs.parsers.TextReader.__cinit__
pandas.errors.EmptyDataError: No columns to parse from file

2024-08-11T10:51:38.089Z - Error generating graph for PROMIS-10 for Mr_no: 66 - Error: Command failed: python3 python_scripts/script-d3.py 66 "PROMIS-10"
Traceback (most recent call last):
  File "/Users/vijaychagantipati/Documents/Developer/node projects/proms/Doctor_Login_Page/python_scripts/script-d3.py", line 2301, in <module>
    combine_all_csvs(mr_no)
  File "/Users/vijaychagantipati/Documents/Developer/node projects/proms/Doctor_Login_Page/python_scripts/script-d3.py", line 1545, in combine_all_csvs
    df = pd.read_csv(csv_file)
         ^^^^^^^^^^^^^^^^^^^^^
  File "/opt/anaconda3/lib/python3.11/site-packages/pandas/io/parsers/readers.py", line 948, in read_csv
    return _read(filepath_or_buffer, kwds)
           ^^^^^^^^^^^^^^^^^^^^^^^^^^^^^^^
  File "/opt/anaconda3/lib/python3.11/site-packages/pandas/io/parsers/readers.py", line 611, in _read
    parser = TextFileReader(filepath_or_buffer, **kwds)
             ^^^^^^^^^^^^^^^^^^^^^^^^^^^^^^^^^^^^^^^^^^
  File "/opt/anaconda3/lib/python3.11/site-packages/pandas/io/parsers/readers.py", line 1448, in __init__
    self._engine = self._make_engine(f, self.engine)
                   ^^^^^^^^^^^^^^^^^^^^^^^^^^^^^^^^^
  File "/opt/anaconda3/lib/python3.11/site-packages/pandas/io/parsers/readers.py", line 1723, in _make_engine
    return mapping[engine](f, **self.options)
           ^^^^^^^^^^^^^^^^^^^^^^^^^^^^^^^^^^
  File "/opt/anaconda3/lib/python3.11/site-packages/pandas/io/parsers/c_parser_wrapper.py", line 93, in __init__
    self._reader = parsers.TextReader(src, **kwds)
                   ^^^^^^^^^^^^^^^^^^^^^^^^^^^^^^^
  File "parsers.pyx", line 586, in pandas._libs.parsers.TextReader.__cinit__
pandas.errors.EmptyDataError: No columns to parse from file

2024-08-13T16:19:16.045Z - Error generating graph for ICIQ-UI_SF for Mr_no: 66 - Error: Command failed: python3 python_scripts/script-d3.py 66 "ICIQ-UI_SF"
Traceback (most recent call last):
  File "/Users/vijaychagantipati/Documents/Developer/node projects/proms/Doctor_Login_Page/python_scripts/script-d3.py", line 2301, in <module>
    combine_all_csvs(mr_no)
  File "/Users/vijaychagantipati/Documents/Developer/node projects/proms/Doctor_Login_Page/python_scripts/script-d3.py", line 1545, in combine_all_csvs
    df = pd.read_csv(csv_file)
         ^^^^^^^^^^^^^^^^^^^^^
  File "/opt/anaconda3/lib/python3.11/site-packages/pandas/io/parsers/readers.py", line 948, in read_csv
    return _read(filepath_or_buffer, kwds)
           ^^^^^^^^^^^^^^^^^^^^^^^^^^^^^^^
  File "/opt/anaconda3/lib/python3.11/site-packages/pandas/io/parsers/readers.py", line 611, in _read
    parser = TextFileReader(filepath_or_buffer, **kwds)
             ^^^^^^^^^^^^^^^^^^^^^^^^^^^^^^^^^^^^^^^^^^
  File "/opt/anaconda3/lib/python3.11/site-packages/pandas/io/parsers/readers.py", line 1448, in __init__
    self._engine = self._make_engine(f, self.engine)
                   ^^^^^^^^^^^^^^^^^^^^^^^^^^^^^^^^^
  File "/opt/anaconda3/lib/python3.11/site-packages/pandas/io/parsers/readers.py", line 1723, in _make_engine
    return mapping[engine](f, **self.options)
           ^^^^^^^^^^^^^^^^^^^^^^^^^^^^^^^^^^
  File "/opt/anaconda3/lib/python3.11/site-packages/pandas/io/parsers/c_parser_wrapper.py", line 93, in __init__
    self._reader = parsers.TextReader(src, **kwds)
                   ^^^^^^^^^^^^^^^^^^^^^^^^^^^^^^^
  File "parsers.pyx", line 586, in pandas._libs.parsers.TextReader.__cinit__
pandas.errors.EmptyDataError: No columns to parse from file

2024-08-13T16:48:33.481Z - Error generating graph for EPDS for Mr_no: 66 - Error: Command failed: python3 python_scripts/script-d3.py 66 "EPDS"
Traceback (most recent call last):
  File "/Users/vijaychagantipati/Documents/Developer/node projects/proms/Doctor_Login_Page/python_scripts/script-d3.py", line 2301, in <module>
    combine_all_csvs(mr_no)
  File "/Users/vijaychagantipati/Documents/Developer/node projects/proms/Doctor_Login_Page/python_scripts/script-d3.py", line 1545, in combine_all_csvs
    df = pd.read_csv(csv_file)
         ^^^^^^^^^^^^^^^^^^^^^
  File "/opt/anaconda3/lib/python3.11/site-packages/pandas/io/parsers/readers.py", line 948, in read_csv
    return _read(filepath_or_buffer, kwds)
           ^^^^^^^^^^^^^^^^^^^^^^^^^^^^^^^
  File "/opt/anaconda3/lib/python3.11/site-packages/pandas/io/parsers/readers.py", line 611, in _read
    parser = TextFileReader(filepath_or_buffer, **kwds)
             ^^^^^^^^^^^^^^^^^^^^^^^^^^^^^^^^^^^^^^^^^^
  File "/opt/anaconda3/lib/python3.11/site-packages/pandas/io/parsers/readers.py", line 1448, in __init__
    self._engine = self._make_engine(f, self.engine)
                   ^^^^^^^^^^^^^^^^^^^^^^^^^^^^^^^^^
  File "/opt/anaconda3/lib/python3.11/site-packages/pandas/io/parsers/readers.py", line 1723, in _make_engine
    return mapping[engine](f, **self.options)
           ^^^^^^^^^^^^^^^^^^^^^^^^^^^^^^^^^^
  File "/opt/anaconda3/lib/python3.11/site-packages/pandas/io/parsers/c_parser_wrapper.py", line 93, in __init__
    self._reader = parsers.TextReader(src, **kwds)
                   ^^^^^^^^^^^^^^^^^^^^^^^^^^^^^^^
  File "parsers.pyx", line 586, in pandas._libs.parsers.TextReader.__cinit__
pandas.errors.EmptyDataError: No columns to parse from file

2024-08-15T06:43:51.305Z - Error during login for username Ravi_2: Doctor is not defined
2024-08-15T06:45:46.042Z - Error during login for username Ravi_2: Operation `doctors.findOne()` buffering timed out after 10000ms
2024-08-15T06:48:44.206Z - Error during login for username Ravi_2: Doctor is not defined
2024-08-15T06:53:08.135Z - Error during login for username Ravi_2: Doctor is not defined
2024-08-20T10:28:44.698Z - Error generating graph for PROMIS-10_d for Mr_no: 798 - Error: Command failed: python3 python_scripts/script-d3.py 798 "PROMIS-10_d"
Traceback (most recent call last):
  File "/opt/anaconda3/lib/python3.11/site-packages/pandas/core/indexes/base.py", line 3791, in get_loc
    return self._engine.get_loc(casted_key)
           ^^^^^^^^^^^^^^^^^^^^^^^^^^^^^^^^
  File "index.pyx", line 152, in pandas._libs.index.IndexEngine.get_loc
  File "index.pyx", line 181, in pandas._libs.index.IndexEngine.get_loc
  File "pandas/_libs/hashtable_class_helper.pxi", line 7080, in pandas._libs.hashtable.PyObjectHashTable.get_item
  File "pandas/_libs/hashtable_class_helper.pxi", line 7088, in pandas._libs.hashtable.PyObjectHashTable.get_item
KeyError: 'trace_name'

The above exception was the direct cause of the following exception:

Traceback (most recent call last):
  File "/Users/vijaychagantipati/Documents/Developer/node projects/proms/Doctor_Login_Page/python_scripts/script-d3.py", line 2367, in <module>
    combine_all_csvs(mr_no)
  File "/Users/vijaychagantipati/Documents/Developer/node projects/proms/Doctor_Login_Page/python_scripts/script-d3.py", line 1616, in combine_all_csvs
    combined_df['trace_name'] = combined_df['trace_name'].replace({
                                ~~~~~~~~~~~^^^^^^^^^^^^^^
  File "/opt/anaconda3/lib/python3.11/site-packages/pandas/core/frame.py", line 3893, in __getitem__
    indexer = self.columns.get_loc(key)
              ^^^^^^^^^^^^^^^^^^^^^^^^^
  File "/opt/anaconda3/lib/python3.11/site-packages/pandas/core/indexes/base.py", line 3798, in get_loc
    raise KeyError(key) from err
KeyError: 'trace_name'

2024-08-20T10:28:44.700Z - Error generating graph for PAID for Mr_no: 798 - Error: Command failed: python3 python_scripts/script-d3.py 798 "PAID"
Traceback (most recent call last):
  File "/opt/anaconda3/lib/python3.11/site-packages/pandas/core/indexes/base.py", line 3791, in get_loc
    return self._engine.get_loc(casted_key)
           ^^^^^^^^^^^^^^^^^^^^^^^^^^^^^^^^
  File "index.pyx", line 152, in pandas._libs.index.IndexEngine.get_loc
  File "index.pyx", line 181, in pandas._libs.index.IndexEngine.get_loc
  File "pandas/_libs/hashtable_class_helper.pxi", line 7080, in pandas._libs.hashtable.PyObjectHashTable.get_item
  File "pandas/_libs/hashtable_class_helper.pxi", line 7088, in pandas._libs.hashtable.PyObjectHashTable.get_item
KeyError: 'trace_name'

The above exception was the direct cause of the following exception:

Traceback (most recent call last):
  File "/Users/vijaychagantipati/Documents/Developer/node projects/proms/Doctor_Login_Page/python_scripts/script-d3.py", line 2367, in <module>
    combine_all_csvs(mr_no)
  File "/Users/vijaychagantipati/Documents/Developer/node projects/proms/Doctor_Login_Page/python_scripts/script-d3.py", line 1616, in combine_all_csvs
    combined_df['trace_name'] = combined_df['trace_name'].replace({
                                ~~~~~~~~~~~^^^^^^^^^^^^^^
  File "/opt/anaconda3/lib/python3.11/site-packages/pandas/core/frame.py", line 3893, in __getitem__
    indexer = self.columns.get_loc(key)
              ^^^^^^^^^^^^^^^^^^^^^^^^^
  File "/opt/anaconda3/lib/python3.11/site-packages/pandas/core/indexes/base.py", line 3798, in get_loc
    raise KeyError(key) from err
KeyError: 'trace_name'

